<sdf version='1.6'>
  <world name='default'>
    <light name='sun' type='directional'>
      <cast_shadows>1</cast_shadows>
      <pose frame=''>0 0 10 0 -0 0</pose>
      <diffuse>0.8 0.8 0.8 1</diffuse>
      <specular>0.2 0.2 0.2 1</specular>
      <attenuation>
        <range>1000</range>
        <constant>0.9</constant>
        <linear>0.01</linear>
        <quadratic>0.001</quadratic>
      </attenuation>
      <direction>-0.5 0.1 -0.9</direction>
    </light>
    <model name='ground_plane'>
      <static>1</static>
      <link name='link'>
        <collision name='collision'>
          <geometry>
            <plane>
              <normal>0 0 1</normal>
              <size>100 100</size>
            </plane>
          </geometry>
          <surface>
            <contact>
              <collide_bitmask>65535</collide_bitmask>
              <ode/>
            </contact>
            <friction>
              <ode>
                <mu>100</mu>
                <mu2>50</mu2>
              </ode>
              <torsional>
                <ode/>
              </torsional>
            </friction>
            <bounce/>
          </surface>
          <max_contacts>10</max_contacts>
        </collision>
        <visual name='visual'>
          <cast_shadows>0</cast_shadows>
          <geometry>
            <plane>
              <normal>0 0 1</normal>
              <size>100 100</size>
            </plane>
          </geometry>
          <material>
            <script>
              <uri>file://media/materials/scripts/gazebo.material</uri>
              <name>Gazebo/Grey</name>
            </script>
          </material>
        </visual>
        <self_collide>0</self_collide>
        <enable_wind>0</enable_wind>
        <kinematic>0</kinematic>
      </link>
    </model>
    <gravity>0 0 -9.8</gravity>
    <magnetic_field>6e-06 2.3e-05 -4.2e-05</magnetic_field>
    <atmosphere type='adiabatic'/>
    <physics name='default_physics' default='0' type='ode'>
      <max_step_size>0.001</max_step_size>
      <real_time_factor>1</real_time_factor>
      <real_time_update_rate>1000</real_time_update_rate>
    </physics>
    <scene>
      <ambient>0.4 0.4 0.4 1</ambient>
      <background>0.7 0.7 0.7 1</background>
      <shadows>1</shadows>
    </scene>
    <wind/>
    <spherical_coordinates>
      <surface_model>EARTH_WGS84</surface_model>
      <latitude_deg>0</latitude_deg>
      <longitude_deg>0</longitude_deg>
      <elevation>0</elevation>
      <heading_deg>0</heading_deg>
    </spherical_coordinates>
    <model name='goal'>
      <link name='Goal'>
        <pose frame=''>0 0 0 0 -0 0</pose>
        <inertial>
          <pose frame=''>0 0 0 0 -0 0</pose>
          <mass>1</mass>
          <inertia>
            <ixx>1</ixx>
            <ixy>0</ixy>
            <ixz>0</ixz>
            <iyy>1</iyy>
            <iyz>0</iyz>
            <izz>1</izz>
          </inertia>
        </inertial>
        <visual name='Goal_visual'>
          <pose frame=''>0 0 0 0 -0 0</pose>
          <geometry>
            <box>
              <size>0.2 0.2 0.2</size>
            </box>
          </geometry>
          <material>
            <script>
              <name>Gazebo/Red</name>
              <uri>file://media/materials/scripts/gazebo.material</uri>
            </script>
          </material>
        </visual>
        <gravity>0</gravity>
        <velocity_decay/>
        <gravity>0</gravity>
        <self_collide>0</self_collide>
        <enable_wind>0</enable_wind>
        <kinematic>0</kinematic>
      </link>
      <pose frame=''>0 0 1 0 -0 0</pose>
    </model>
    <model name='mp500lwa4d'>
      <link name='base_footprint'>
        <pose frame=''>0 0 0 0 -0 0</pose>
        <inertial>
          <pose frame=''>0.002356 0 0.012029 0 -0 0</pose>
          <mass>1.04</mass>
          <inertia>
            <ixx>1.00886</ixx>
            <ixy>-1.05879e-22</ixy>
            <ixz>-0.000789129</ixz>
            <iyy>1.01174</iyy>
            <iyz>-1.68629e-25</iyz>
            <izz>1.00719</izz>
          </inertia>
        </inertial>
        <collision name='base_footprint_fixed_joint_lump__body_collision_collision'>
          <pose frame=''>0 0 0.216 0 0 -1.57</pose>
          <geometry>
            <box>
              <size>0.4 0.676 0.3</size>
            </box>
          </geometry>
          <max_contacts>10</max_contacts>
          <surface>
            <contact>
              <ode/>
            </contact>
            <bounce/>
            <friction>
              <torsional>
                <ode/>
              </torsional>
              <ode/>
            </friction>
          </surface>
        </collision>
        <collision name='base_footprint_fixed_joint_lump__arm_podest_link_collision_1'>
          <pose frame=''>0.19 0 0.36 0 -0 0</pose>
          <geometry>
            <mesh>
              <scale>1 1 1</scale>
              <uri>/home/jingzhe/WorkSpace/ROS/mp500lwa4d_robot_env/src/mp500lwa4d_description/meshes/lwa4d/arm_podest_link.stl</uri>
            </mesh>
          </geometry>
          <max_contacts>10</max_contacts>
          <surface>
            <contact>
              <ode/>
            </contact>
            <bounce/>
            <friction>
              <torsional>
                <ode/>
              </torsional>
              <ode/>
            </friction>
          </surface>
        </collision>
        <collision name='base_footprint_fixed_joint_lump__hanger_collision_2'>
          <pose frame=''>0.255 0 0.11 0 0 -1.57</pose>
          <geometry>
            <mesh>
              <scale>0.01 0.01 0.01</scale>
              <uri>/home/jingzhe/WorkSpace/ROS/mp500lwa4d_robot_env/src/mp500lwa4d_description/meshes/mp500/HANGER-WHEEL.STL</uri>
            </mesh>
          </geometry>
          <surface>
            <contact>
              <ode>
                <kp>1e+06</kp>
                <kd>100</kd>
              </ode>
            </contact>
            <friction>
              <ode>
                <mu>0.1</mu>
                <mu2>0.1</mu2>
              </ode>
              <torsional>
                <ode/>
              </torsional>
            </friction>
            <bounce/>
          </surface>
          <max_contacts>10</max_contacts>
        </collision>
        <collision name='base_footprint_fixed_joint_lump__laserscanner_front_link_collision_3'>
          <pose frame=''>-0.39 0 0.281 3.14 -0 -1.57</pose>
          <geometry>
            <cylinder>
              <length>0.154</length>
              <radius>0.053</radius>
            </cylinder>
          </geometry>
          <surface>
            <contact>
              <ode/>
            </contact>
            <friction>
              <ode/>
              <torsional>
                <ode/>
              </torsional>
            </friction>
            <bounce/>
          </surface>
          <max_contacts>10</max_contacts>
        </collision>
        <visual name='base_footprint_visual'>
          <pose frame=''>0 0 0 0 -0 0</pose>
          <geometry>
            <box>
              <size>0.001 0.001 0.001</size>
            </box>
          </geometry>
          <material>
            <script>
              <name>Gazebo/Grey</name>
              <uri>file://media/materials/scripts/gazebo.material</uri>
            </script>
          </material>
        </visual>
        <visual name='base_footprint_fixed_joint_lump__body_visual_1'>
          <pose frame=''>-0.16 0 0.09 0 0 -1.57</pose>
          <geometry>
            <mesh>
              <scale>0.01 0.01 0.01</scale>
              <uri>/home/jingzhe/WorkSpace/ROS/mp500lwa4d_robot_env/src/mp500lwa4d_description/meshes/mp500/MP500-BODY.STL</uri>
            </mesh>
          </geometry>
        </visual>
        <visual name='base_footprint_fixed_joint_lump__arm_podest_link_visual_2'>
          <pose frame=''>0.19 0 0.36 0 -0 0</pose>
          <geometry>
            <mesh>
              <scale>1 1 1</scale>
              <uri>/home/jingzhe/WorkSpace/ROS/mp500lwa4d_robot_env/src/mp500lwa4d_description/meshes/lwa4d/arm_podest_link.stl</uri>
            </mesh>
          </geometry>
        </visual>
        <visual name='base_footprint_fixed_joint_lump__hanger_visual_3'>
          <pose frame=''>0.255 0 0.11 0 0 -1.57</pose>
          <geometry>
            <mesh>
              <scale>0.01 0.01 0.01</scale>
              <uri>/home/jingzhe/WorkSpace/ROS/mp500lwa4d_robot_env/src/mp500lwa4d_description/meshes/mp500/HANGER-WHEEL.STL</uri>
            </mesh>
          </geometry>
          <material>
            <script>
              <name>Gazebo/Grey</name>
              <uri>file://media/materials/scripts/gazebo.material</uri>
            </script>
          </material>
        </visual>
        <visual name='base_footprint_fixed_joint_lump__laserscanner_front_link_visual_4'>
          <pose frame=''>-0.39 0 0.241 3.14 -0 -1.57</pose>
          <geometry>
            <mesh>
              <scale>1 1 1</scale>
              <uri>/home/jingzhe/WorkSpace/ROS/mp500lwa4d_robot_env/src/mp500lwa4d_description/meshes/mp500/SICK-S300.STL</uri>
            </mesh>
          </geometry>
          <material>
            <script>
              <name>Gazebo/Grey</name>
              <uri>file://media/materials/scripts/gazebo.material</uri>
            </script>
          </material>
        </visual>
        <velocity_decay/>
        <velocity_decay/>
        <velocity_decay/>
        <self_collide>0</self_collide>
        <gravity>1</gravity>
        <velocity_decay/>
        <gravity>1</gravity>
        <gravity>1</gravity>
        <velocity_decay/>
        <gravity>1</gravity>
        <velocity_decay/>
        <sensor name='rplidar' type='ray'>
          <visualize>0</visualize>
          <update_rate>5.5</update_rate>
          <ray>
            <scan>
              <horizontal>
                <samples>360</samples>
                <resolution>1</resolution>
                <min_angle>-3</min_angle>
                <max_angle>3</max_angle>
              </horizontal>
              <vertical>
                <samples>1</samples>
                <min_angle>0</min_angle>
                <max_angle>0</max_angle>
              </vertical>
            </scan>
            <range>
              <min>0.1</min>
              <max>6</max>
              <resolution>0.01</resolution>
            </range>
            <noise>
              <type>gaussian</type>
              <mean>0</mean>
              <stddev>0.01</stddev>
            </noise>
          </ray>
          <plugin name='gazebo_rplidar' filename='libgazebo_ros_laser.so'>
            <topicName>/scan</topicName>
            <frameName>laser_link</frameName>
            <robotNamespace>/</robotNamespace>
          </plugin>
          <pose frame=''>-0.39 0 0.281 0 -0 0</pose>
        </sensor>
        <enable_wind>0</enable_wind>
        <kinematic>0</kinematic>
      </link>
      <link name='arm_1_link'>
        <pose frame=''>0.19 0 0.5 0 -0 0</pose>
        <inertial>
          <pose frame=''>0 0 0 0 -0 0</pose>
          <mass>0.01</mass>
          <inertia>
            <ixx>0.001</ixx>
            <ixy>0</ixy>
            <ixz>0</ixz>
            <iyy>0.001</iyy>
            <iyz>0</iyz>
            <izz>0.001</izz>
          </inertia>
        </inertial>
        <collision name='arm_1_link_collision'>
          <pose frame=''>0 0 0 0 -0 0</pose>
          <geometry>
            <mesh>
              <scale>1 1 1</scale>
              <uri>/home/jingzhe/WorkSpace/ROS/mp500lwa4d_robot_env/src/mp500lwa4d_description/meshes/lwa4d/arm_1_link.stl</uri>
            </mesh>
          </geometry>
          <surface>
            <contact>
              <ode/>
            </contact>
            <friction>
              <ode/>
              <torsional>
                <ode/>
              </torsional>
            </friction>
            <bounce/>
          </surface>
          <max_contacts>10</max_contacts>
        </collision>
        <visual name='arm_1_link_visual'>
          <pose frame=''>0 0 0 0 -0 0</pose>
          <geometry>
            <mesh>
              <scale>1 1 1</scale>
              <uri>/home/jingzhe/WorkSpace/ROS/mp500lwa4d_robot_env/src/mp500lwa4d_description/meshes/lwa4d/arm_1_link.stl</uri>
            </mesh>
          </geometry>
          <material>
            <script>
              <name>Gazebo/Grey</name>
              <uri>file://media/materials/scripts/gazebo.material</uri>
            </script>
          </material>
        </visual>
        <gravity>1</gravity>
        <velocity_decay/>
        <gravity>1</gravity>
        <self_collide>0</self_collide>
        <enable_wind>0</enable_wind>
        <kinematic>0</kinematic>
      </link>
      <joint name='arm_1_joint' type='revolute'>
        <child>arm_1_link</child>
        <parent>base_footprint</parent>
        <axis>
          <xyz>0 0 1</xyz>
          <limit>
            <lower>-3.12159</lower>
            <upper>3.12159</upper>
            <effort>216</effort>
            <velocity>0.43633</velocity>
          </limit>
          <dynamics>
            <damping>0</damping>
            <friction>0</friction>
            <spring_reference>0</spring_reference>
            <spring_stiffness>0</spring_stiffness>
          </dynamics>
          <use_parent_model_frame>1</use_parent_model_frame>
        </axis>
      </joint>
      <link name='arm_2_link'>
        <pose frame=''>0.19 0 0.74 1.57079 -1.57079 3.14159</pose>
        <inertial>
          <pose frame=''>0 0 0 0 -0 0</pose>
          <mass>0.01</mass>
          <inertia>
            <ixx>0.001</ixx>
            <ixy>0</ixy>
            <ixz>0</ixz>
            <iyy>0.001</iyy>
            <iyz>0</iyz>
            <izz>0.001</izz>
          </inertia>
        </inertial>
        <collision name='arm_2_link_collision'>
          <pose frame=''>0 0 0 0 -0 0</pose>
          <geometry>
            <mesh>
              <scale>1 1 1</scale>
              <uri>/home/jingzhe/WorkSpace/ROS/mp500lwa4d_robot_env/src/mp500lwa4d_description/meshes/lwa4d/arm_2_link_collision.stl</uri>
            </mesh>
          </geometry>
          <surface>
            <contact>
              <ode/>
            </contact>
            <friction>
              <ode/>
              <torsional>
                <ode/>
              </torsional>
            </friction>
            <bounce/>
          </surface>
          <max_contacts>10</max_contacts>
        </collision>
        <visual name='arm_2_link_visual'>
          <pose frame=''>0 0 0 0 -0 0</pose>
          <geometry>
            <mesh>
              <scale>1 1 1</scale>
              <uri>/home/jingzhe/WorkSpace/ROS/mp500lwa4d_robot_env/src/mp500lwa4d_description/meshes/lwa4d/arm_2_link.stl</uri>
            </mesh>
          </geometry>
          <material>
            <script>
              <name>Gazebo/Black</name>
              <uri>file://media/materials/scripts/gazebo.material</uri>
            </script>
          </material>
        </visual>
        <gravity>1</gravity>
        <velocity_decay/>
        <gravity>1</gravity>
        <self_collide>0</self_collide>
        <enable_wind>0</enable_wind>
        <kinematic>0</kinematic>
      </link>
      <joint name='arm_2_joint' type='revolute'>
        <child>arm_2_link</child>
        <parent>arm_1_link</parent>
        <axis>
          <xyz>-0 1 0</xyz>
          <limit>
            <lower>-2.12</lower>
            <upper>2.12</upper>
            <effort>216</effort>
            <velocity>0.43633</velocity>
          </limit>
          <dynamics>
            <damping>0.9</damping>
            <friction>0.08</friction>
            <spring_reference>0</spring_reference>
            <spring_stiffness>0</spring_stiffness>
          </dynamics>
          <use_parent_model_frame>1</use_parent_model_frame>
        </axis>
      </joint>
      <link name='arm_3_link'>
        <pose frame=''>0.19 0 0.74 0 -0 0</pose>
        <inertial>
          <pose frame=''>0 0 0 0 -0 0</pose>
          <mass>0.01</mass>
          <inertia>
            <ixx>0.001</ixx>
            <ixy>0</ixy>
            <ixz>0</ixz>
            <iyy>0.001</iyy>
            <iyz>0</iyz>
            <izz>0.001</izz>
          </inertia>
        </inertial>
        <collision name='arm_3_link_collision'>
          <pose frame=''>0 0 0 0 -0 0</pose>
          <geometry>
            <mesh>
              <scale>1 1 1</scale>
              <uri>/home/jingzhe/WorkSpace/ROS/mp500lwa4d_robot_env/src/mp500lwa4d_description/meshes/lwa4d/arm_3_link_collision.stl</uri>
            </mesh>
          </geometry>
          <surface>
            <contact>
              <ode/>
            </contact>
            <friction>
              <ode/>
              <torsional>
                <ode/>
              </torsional>
            </friction>
            <bounce/>
          </surface>
          <max_contacts>10</max_contacts>
        </collision>
        <visual name='arm_3_link_visual'>
          <pose frame=''>0 0 0 0 -0 0</pose>
          <geometry>
            <mesh>
              <scale>1 1 1</scale>
              <uri>/home/jingzhe/WorkSpace/ROS/mp500lwa4d_robot_env/src/mp500lwa4d_description/meshes/lwa4d/arm_3_link.stl</uri>
            </mesh>
          </geometry>
          <material>
            <script>
              <name>Gazebo/Grey</name>
              <uri>file://media/materials/scripts/gazebo.material</uri>
            </script>
          </material>
        </visual>
        <gravity>1</gravity>
        <velocity_decay/>
        <gravity>1</gravity>
        <self_collide>0</self_collide>
        <enable_wind>0</enable_wind>
        <kinematic>0</kinematic>
      </link>
      <joint name='arm_3_joint' type='revolute'>
        <child>arm_3_link</child>
        <parent>arm_2_link</parent>
        <axis>
          <xyz>-0 0 1</xyz>
          <limit>
            <lower>-3.12159</lower>
            <upper>3.12159</upper>
            <effort>81.5</effort>
            <velocity>0.4189</velocity>
          </limit>
          <dynamics>
            <damping>0</damping>
            <friction>0</friction>
            <spring_reference>0</spring_reference>
            <spring_stiffness>0</spring_stiffness>
          </dynamics>
          <use_parent_model_frame>1</use_parent_model_frame>
        </axis>
      </joint>
      <link name='arm_4_link'>
        <pose frame=''>0.19 0 1.068 1.57079 -1.57079 3.14159</pose>
        <inertial>
          <pose frame=''>0 0 0 0 -0 0</pose>
          <mass>0.01</mass>
          <inertia>
            <ixx>0.001</ixx>
            <ixy>0</ixy>
            <ixz>0</ixz>
            <iyy>0.001</iyy>
            <iyz>0</iyz>
            <izz>0.001</izz>
          </inertia>
        </inertial>
        <collision name='arm_4_link_collision'>
          <pose frame=''>0 0 0 0 -0 0</pose>
          <geometry>
            <mesh>
              <scale>1 1 1</scale>
              <uri>/home/jingzhe/WorkSpace/ROS/mp500lwa4d_robot_env/src/mp500lwa4d_description/meshes/lwa4d/arm_4_link_collision.stl</uri>
            </mesh>
          </geometry>
          <surface>
            <contact>
              <ode/>
            </contact>
            <friction>
              <ode/>
              <torsional>
                <ode/>
              </torsional>
            </friction>
            <bounce/>
          </surface>
          <max_contacts>10</max_contacts>
        </collision>
        <visual name='arm_4_link_visual'>
          <pose frame=''>0 0 0 0 -0 0</pose>
          <geometry>
            <mesh>
              <scale>1 1 1</scale>
              <uri>/home/jingzhe/WorkSpace/ROS/mp500lwa4d_robot_env/src/mp500lwa4d_description/meshes/lwa4d/arm_4_link.stl</uri>
            </mesh>
          </geometry>
          <material>
            <script>
              <name>Gazebo/Black</name>
              <uri>file://media/materials/scripts/gazebo.material</uri>
            </script>
          </material>
        </visual>
        <gravity>1</gravity>
        <velocity_decay/>
        <gravity>1</gravity>
        <self_collide>0</self_collide>
        <enable_wind>0</enable_wind>
        <kinematic>0</kinematic>
      </link>
      <joint name='arm_4_joint' type='revolute'>
        <child>arm_4_link</child>
        <parent>arm_3_link</parent>
        <axis>
          <xyz>-0 1 -0</xyz>
          <limit>
            <lower>-2.16</lower>
            <upper>2.16</upper>
            <effort>81.5</effort>
            <velocity>0.4189</velocity>
          </limit>
          <dynamics>
            <damping>0.9</damping>
            <friction>0.08</friction>
            <spring_reference>0</spring_reference>
            <spring_stiffness>0</spring_stiffness>
          </dynamics>
          <use_parent_model_frame>1</use_parent_model_frame>
        </axis>
      </joint>
      <link name='arm_5_link'>
        <pose frame=''>0.19 0 1.068 0 -0 0</pose>
        <inertial>
          <pose frame=''>0 0 0 0 -0 0</pose>
          <mass>0.01</mass>
          <inertia>
            <ixx>0.001</ixx>
            <ixy>0</ixy>
            <ixz>0</ixz>
            <iyy>0.001</iyy>
            <iyz>0</iyz>
            <izz>0.001</izz>
          </inertia>
        </inertial>
        <collision name='arm_5_link_collision'>
          <pose frame=''>0 0 0 0 -0 0</pose>
          <geometry>
            <mesh>
              <scale>1 1 1</scale>
              <uri>/home/jingzhe/WorkSpace/ROS/mp500lwa4d_robot_env/src/mp500lwa4d_description/meshes/lwa4d/arm_5_link_collision.stl</uri>
            </mesh>
          </geometry>
          <surface>
            <contact>
              <ode/>
            </contact>
            <friction>
              <ode/>
              <torsional>
                <ode/>
              </torsional>
            </friction>
            <bounce/>
          </surface>
          <max_contacts>10</max_contacts>
        </collision>
        <visual name='arm_5_link_visual'>
          <pose frame=''>0 0 0 0 -0 0</pose>
          <geometry>
            <mesh>
              <scale>1 1 1</scale>
              <uri>/home/jingzhe/WorkSpace/ROS/mp500lwa4d_robot_env/src/mp500lwa4d_description/meshes/lwa4d/arm_5_link.stl</uri>
            </mesh>
          </geometry>
          <material>
            <script>
              <name>Gazebo/Grey</name>
              <uri>file://media/materials/scripts/gazebo.material</uri>
            </script>
          </material>
        </visual>
        <gravity>1</gravity>
        <velocity_decay/>
        <gravity>1</gravity>
        <self_collide>0</self_collide>
        <enable_wind>0</enable_wind>
        <kinematic>0</kinematic>
      </link>
      <joint name='arm_5_joint' type='revolute'>
        <child>arm_5_link</child>
        <parent>arm_4_link</parent>
        <axis>
          <xyz>-0 0 1</xyz>
          <limit>
            <lower>-3.12159</lower>
            <upper>3.12159</upper>
            <effort>20.7</effort>
            <velocity>0.43633</velocity>
          </limit>
          <dynamics>
            <damping>0</damping>
            <friction>0</friction>
            <spring_reference>0</spring_reference>
            <spring_stiffness>0</spring_stiffness>
          </dynamics>
          <use_parent_model_frame>1</use_parent_model_frame>
        </axis>
      </joint>
      <link name='arm_6_link'>
        <pose frame=''>0.19 0 1.391 1.57079 -1.57079 3.14159</pose>
        <inertial>
          <pose frame=''>0 0 0 0 -0 0</pose>
          <mass>0.01</mass>
          <inertia>
            <ixx>0.001</ixx>
            <ixy>0</ixy>
            <ixz>0</ixz>
            <iyy>0.001</iyy>
            <iyz>0</iyz>
            <izz>0.001</izz>
          </inertia>
        </inertial>
        <collision name='arm_6_link_collision'>
          <pose frame=''>0 0 0 0 -0 0</pose>
          <geometry>
            <mesh>
              <scale>1 1 1</scale>
              <uri>/home/jingzhe/WorkSpace/ROS/mp500lwa4d_robot_env/src/mp500lwa4d_description/meshes/lwa4d/arm_6_link_collision.stl</uri>
            </mesh>
          </geometry>
          <surface>
            <contact>
              <ode/>
            </contact>
            <friction>
              <ode/>
              <torsional>
                <ode/>
              </torsional>
            </friction>
            <bounce/>
          </surface>
          <max_contacts>10</max_contacts>
        </collision>
        <visual name='arm_6_link_visual'>
          <pose frame=''>0 0 0 0 -0 0</pose>
          <geometry>
            <mesh>
              <scale>1 1 1</scale>
              <uri>/home/jingzhe/WorkSpace/ROS/mp500lwa4d_robot_env/src/mp500lwa4d_description/meshes/lwa4d/arm_6_link.stl</uri>
            </mesh>
          </geometry>
          <material>
            <script>
              <name>Gazebo/Black</name>
              <uri>file://media/materials/scripts/gazebo.material</uri>
            </script>
          </material>
        </visual>
        <gravity>1</gravity>
        <velocity_decay/>
        <gravity>1</gravity>
        <self_collide>0</self_collide>
        <enable_wind>0</enable_wind>
        <kinematic>0</kinematic>
      </link>
      <joint name='arm_6_joint' type='revolute'>
        <child>arm_6_link</child>
        <parent>arm_5_link</parent>
        <axis>
          <xyz>-0 1 -0</xyz>
          <limit>
            <lower>-2.94</lower>
            <upper>2.94</upper>
            <effort>15</effort>
            <velocity>1.2566</velocity>
          </limit>
          <dynamics>
            <damping>0</damping>
            <friction>0</friction>
            <spring_reference>0</spring_reference>
            <spring_stiffness>0</spring_stiffness>
          </dynamics>
          <use_parent_model_frame>1</use_parent_model_frame>
        </axis>
      </joint>
      <link name='arm_7_link'>
        <pose frame=''>0.19 0 1.391 0 -0 0</pose>
        <inertial>
          <pose frame=''>0 0 0.013733 0 -0 0</pose>
          <mass>0.012</mass>
          <inertia>
            <ixx>0.00121132</ixx>
            <ixy>0</ixy>
            <ixz>0</ixz>
            <iyy>0.00121132</iyy>
            <iyz>0</iyz>
            <izz>0.0012</izz>
          </inertia>
        </inertial>
        <collision name='arm_7_link_collision'>
          <pose frame=''>0 0 0 0 -0 0</pose>
          <geometry>
            <mesh>
              <scale>1 1 1</scale>
              <uri>/home/jingzhe/WorkSpace/ROS/mp500lwa4d_robot_env/src/mp500lwa4d_description/meshes/lwa4d/arm_7_link.stl</uri>
            </mesh>
          </geometry>
          <surface>
            <contact>
              <ode/>
            </contact>
            <friction>
              <ode/>
              <torsional>
                <ode/>
              </torsional>
            </friction>
            <bounce/>
          </surface>
          <max_contacts>10</max_contacts>
        </collision>
        <collision name='arm_7_link_fixed_joint_lump__gripper_podest_link_collision_1'>
          <pose frame=''>0 0 0.0824 3.14159 -0 3.14159</pose>
          <geometry>
            <mesh>
              <scale>1 1 1</scale>
              <uri>/home/jingzhe/WorkSpace/ROS/mp500lwa4d_robot_env/src/mp500lwa4d_description/meshes/pg70/arm_base_link.stl</uri>
            </mesh>
          </geometry>
          <surface>
            <contact>
              <ode/>
            </contact>
            <friction>
              <ode/>
              <torsional>
                <ode/>
              </torsional>
            </friction>
            <bounce/>
          </surface>
          <max_contacts>10</max_contacts>
        </collision>
        <collision name='arm_7_link_fixed_joint_lump__gripper_palm_link_collision_2'>
          <pose frame=''>0 0 0.11385 0 -0 0</pose>
          <geometry>
            <box>
              <size>0.082 0.114 0.08</size>
            </box>
          </geometry>
          <surface>
            <contact>
              <ode/>
            </contact>
            <friction>
              <ode/>
              <torsional>
                <ode/>
              </torsional>
            </friction>
            <bounce/>
          </surface>
          <max_contacts>10</max_contacts>
        </collision>
        <visual name='arm_7_link_visual'>
          <pose frame=''>0 0 0 0 -0 0</pose>
          <geometry>
            <mesh>
              <scale>1 1 1</scale>
              <uri>/home/jingzhe/WorkSpace/ROS/mp500lwa4d_robot_env/src/mp500lwa4d_description/meshes/lwa4d/arm_7_link.stl</uri>
            </mesh>
          </geometry>
          <material>
            <script>
              <name>Gazebo/Grey</name>
              <uri>file://media/materials/scripts/gazebo.material</uri>
            </script>
          </material>
        </visual>
        <visual name='arm_7_link_fixed_joint_lump__gripper_podest_link_visual_1'>
          <pose frame=''>0 0 0.0824 3.14159 -0 3.14159</pose>
          <geometry>
            <mesh>
              <scale>1 1 1</scale>
              <uri>/home/jingzhe/WorkSpace/ROS/mp500lwa4d_robot_env/src/mp500lwa4d_description/meshes/pg70/arm_base_link.stl</uri>
            </mesh>
          </geometry>
          <material>
            <script>
              <name>Gazebo/Black</name>
              <uri>file://media/materials/scripts/gazebo.material</uri>
            </script>
          </material>
        </visual>
        <visual name='arm_7_link_fixed_joint_lump__gripper_palm_link_visual_2'>
          <pose frame=''>0 0 0.0824 0 -0 0</pose>
          <geometry>
            <mesh>
              <scale>1 1 1</scale>
              <uri>/home/jingzhe/WorkSpace/ROS/mp500lwa4d_robot_env/src/mp500lwa4d_description/meshes/pg70/pg70.dae</uri>
            </mesh>
          </geometry>
          <material>
            <script>
              <name>Gazebo/Black</name>
              <uri>file://media/materials/scripts/gazebo.material</uri>
            </script>
          </material>
        </visual>
        <velocity_decay/>
        <self_collide>0</self_collide>
        <gravity>1</gravity>
        <velocity_decay/>
        <gravity>1</gravity>
        <self_collide>0</self_collide>
        <gravity>1</gravity>
        <velocity_decay/>
        <gravity>1</gravity>
        <self_collide>1</self_collide>
        <enable_wind>0</enable_wind>
        <kinematic>0</kinematic>
      </link>
      <joint name='arm_7_joint' type='revolute'>
        <child>arm_7_link</child>
        <parent>arm_6_link</parent>
        <axis>
          <xyz>-0 0 1</xyz>
          <limit>
            <lower>-2.94</lower>
            <upper>2.94</upper>
            <effort>15</effort>
            <velocity>1.2566</velocity>
          </limit>
          <dynamics>
            <spring_reference>0</spring_reference>
            <spring_stiffness>0</spring_stiffness>
          </dynamics>
          <use_parent_model_frame>1</use_parent_model_frame>
        </axis>
      </joint>
      <link name='gripper_finger_left_link'>
        <pose frame=''>0.19 -0.005 1.5873 0 -0 0</pose>
        <inertial>
          <pose frame=''>0 0 0 0 -0 0</pose>
          <mass>0.001</mass>
          <inertia>
            <ixx>0.0001</ixx>
            <ixy>0</ixy>
            <ixz>0</ixz>
            <iyy>0.0001</iyy>
            <iyz>0</iyz>
            <izz>0.0001</izz>
          </inertia>
        </inertial>
        <collision name='gripper_finger_left_link_collision'>
          <pose frame=''>0 0 0 0 -0 0</pose>
          <geometry>
            <box>
              <size>0.03 0.01 0.08</size>
            </box>
          </geometry>
          <surface>
            <contact>
              <ode/>
            </contact>
            <friction>
              <ode/>
              <torsional>
                <ode/>
              </torsional>
            </friction>
            <bounce/>
          </surface>
          <max_contacts>10</max_contacts>
        </collision>
        <visual name='gripper_finger_left_link_visual'>
          <pose frame=''>0 0 0 0 -0 0</pose>
          <geometry>
            <box>
              <size>0.03 0.01 0.08</size>
            </box>
          </geometry>
          <material>
            <script>
              <name>Gazebo/Grey</name>
              <uri>file://media/materials/scripts/gazebo.material</uri>
            </script>
          </material>
        </visual>
        <gravity>1</gravity>
        <velocity_decay/>
        <gravity>1</gravity>
        <self_collide>0</self_collide>
        <enable_wind>0</enable_wind>
        <kinematic>0</kinematic>
      </link>
      <joint name='gripper_finger_left_joint' type='prismatic'>
        <child>gripper_finger_left_link</child>
        <parent>arm_7_link</parent>
        <axis>
          <xyz>-0 1 -0</xyz>
          <limit>
            <lower>-0.0301</lower>
            <upper>-0.005</upper>
            <effort>10</effort>
            <velocity>0.041</velocity>
          </limit>
          <dynamics>
            <damping>0.08</damping>
            <friction>0.08</friction>
            <spring_reference>0</spring_reference>
            <spring_stiffness>0</spring_stiffness>
          </dynamics>
          <use_parent_model_frame>1</use_parent_model_frame>
        </axis>
      </joint>
      <link name='gripper_finger_right_link'>
        <pose frame=''>0.19 0.005 1.5873 0 -0 0</pose>
        <inertial>
          <pose frame=''>0 0 0 0 -0 0</pose>
          <mass>0.001</mass>
          <inertia>
            <ixx>0.0001</ixx>
            <ixy>0</ixy>
            <ixz>0</ixz>
            <iyy>0.0001</iyy>
            <iyz>0</iyz>
            <izz>0.0001</izz>
          </inertia>
        </inertial>
        <collision name='gripper_finger_right_link_collision'>
          <pose frame=''>0 0 0 0 -0 0</pose>
          <geometry>
            <box>
              <size>0.03 0.01 0.08</size>
            </box>
          </geometry>
          <surface>
            <contact>
              <ode/>
            </contact>
            <friction>
              <ode/>
              <torsional>
                <ode/>
              </torsional>
            </friction>
            <bounce/>
          </surface>
          <max_contacts>10</max_contacts>
        </collision>
        <visual name='gripper_finger_right_link_visual'>
          <pose frame=''>0 0 0 0 -0 0</pose>
          <geometry>
            <box>
              <size>0.03 0.01 0.08</size>
            </box>
          </geometry>
          <material>
            <script>
              <name>Gazebo/Grey</name>
              <uri>file://media/materials/scripts/gazebo.material</uri>
            </script>
          </material>
        </visual>
        <gravity>1</gravity>
        <velocity_decay/>
        <gravity>1</gravity>
        <self_collide>0</self_collide>
        <enable_wind>0</enable_wind>
        <kinematic>0</kinematic>
      </link>
      <joint name='gripper_finger_right_joint' type='prismatic'>
        <child>gripper_finger_right_link</child>
        <parent>arm_7_link</parent>
        <axis>
          <xyz>-0 1 -0</xyz>
          <limit>
            <lower>0.005</lower>
            <upper>0.0301</upper>
            <effort>10</effort>
            <velocity>0.041</velocity>
          </limit>
          <dynamics>
            <damping>0.08</damping>
            <friction>0.08</friction>
            <spring_reference>0</spring_reference>
            <spring_stiffness>0</spring_stiffness>
          </dynamics>
          <use_parent_model_frame>1</use_parent_model_frame>
        </axis>
      </joint>
      <link name='wheel_left_link'>
        <pose frame=''>-0.155 0.255 0.13 0 -0 0</pose>
        <inertial>
          <pose frame=''>0 0 0 0 -0 0</pose>
          <mass>1</mass>
          <inertia>
            <ixx>0.0045</ixx>
            <ixy>0</ixy>
            <ixz>0</ixz>
            <iyy>0.0078</iyy>
            <iyz>0</iyz>
            <izz>0.0045</izz>
          </inertia>
        </inertial>
        <collision name='wheel_left_link_collision'>
          <pose frame=''>0 0 0 -0 1.57 -1.57</pose>
          <geometry>
            <cylinder>
              <length>0.085</length>
              <radius>0.125</radius>
            </cylinder>
          </geometry>
          <surface>
            <contact>
              <ode>
                <kp>1e+06</kp>
                <kd>100</kd>
              </ode>
            </contact>
            <friction>
              <ode>
                <mu>100.5</mu>
                <mu2>100.5</mu2>
                <fdir1>0 0 1</fdir1>
              </ode>
              <torsional>
                <ode/>
              </torsional>
            </friction>
            <bounce/>
          </surface>
          <max_contacts>10</max_contacts>
        </collision>
        <visual name='wheel_left_link_visual'>
          <pose frame=''>0 0 0 0 0 -1.57</pose>
          <geometry>
            <mesh>
              <scale>0.01 0.01 0.01</scale>
              <uri>/home/jingzhe/WorkSpace/ROS/mp500lwa4d_robot_env/src/mp500lwa4d_description/meshes/mp500/MP500-WHEEL.STL</uri>
            </mesh>
          </geometry>
          <material>
            <script>
              <name>Gazebo/Grey</name>
              <uri>file://media/materials/scripts/gazebo.material</uri>
            </script>
          </material>
        </visual>
        <gravity>1</gravity>
        <velocity_decay/>
        <gravity>1</gravity>
        <self_collide>0</self_collide>
        <enable_wind>0</enable_wind>
        <kinematic>0</kinematic>
      </link>
      <joint name='wheel_left_joint' type='revolute'>
        <child>wheel_left_link</child>
        <parent>base_footprint</parent>
        <axis>
          <xyz>0 1 0</xyz>
          <limit>
            <lower>-1e+16</lower>
            <upper>1e+16</upper>
          </limit>
          <dynamics>
            <damping>0</damping>
            <friction>0</friction>
            <spring_reference>0</spring_reference>
            <spring_stiffness>0</spring_stiffness>
          </dynamics>
          <use_parent_model_frame>1</use_parent_model_frame>
        </axis>
      </joint>
      <link name='wheel_right_link'>
        <pose frame=''>-0.155 -0.255 0.13 0 -0 0</pose>
        <inertial>
          <pose frame=''>0 0 0 0 -0 0</pose>
          <mass>1</mass>
          <inertia>
            <ixx>0.0045</ixx>
            <ixy>0</ixy>
            <ixz>0</ixz>
            <iyy>0.0078</iyy>
            <iyz>0</iyz>
            <izz>0.0045</izz>
          </inertia>
        </inertial>
        <collision name='wheel_right_link_collision'>
          <pose frame=''>0 0 0 -0 1.57 -1.57</pose>
          <geometry>
            <cylinder>
              <length>0.085</length>
              <radius>0.125</radius>
            </cylinder>
          </geometry>
          <surface>
            <contact>
              <ode>
                <kp>1e+06</kp>
                <kd>100</kd>
              </ode>
            </contact>
            <friction>
              <ode>
                <mu>100.5</mu>
                <mu2>100.5</mu2>
                <fdir1>0 0 1</fdir1>
              </ode>
              <torsional>
                <ode/>
              </torsional>
            </friction>
            <bounce/>
          </surface>
          <max_contacts>10</max_contacts>
        </collision>
        <visual name='wheel_right_link_visual'>
          <pose frame=''>0 0 0 0 0 -1.57</pose>
          <geometry>
            <mesh>
              <scale>0.01 0.01 0.01</scale>
              <uri>/home/jingzhe/WorkSpace/ROS/mp500lwa4d_robot_env/src/mp500lwa4d_description/meshes/mp500/MP500-WHEEL.STL</uri>
            </mesh>
          </geometry>
          <material>
            <script>
              <name>Gazebo/Grey</name>
              <uri>file://media/materials/scripts/gazebo.material</uri>
            </script>
          </material>
        </visual>
        <gravity>1</gravity>
        <velocity_decay/>
        <gravity>1</gravity>
        <self_collide>0</self_collide>
        <enable_wind>0</enable_wind>
        <kinematic>0</kinematic>
      </link>
      <joint name='wheel_right_joint' type='revolute'>
        <child>wheel_right_link</child>
        <parent>base_footprint</parent>
        <axis>
          <xyz>0 1 0</xyz>
          <limit>
            <lower>-1e+16</lower>
            <upper>1e+16</upper>
          </limit>
          <dynamics>
            <damping>0</damping>
            <friction>0</friction>
            <spring_reference>0</spring_reference>
            <spring_stiffness>0</spring_stiffness>
          </dynamics>
          <use_parent_model_frame>1</use_parent_model_frame>
        </axis>
      </joint>
      <static>0</static>
      <plugin name='gazebo_ros_control' filename='libgazebo_ros_control.so'>
        <robotNamespace>/mp500lwa4d</robotNamespace>
        <robotBaseFrame>base_footprint</robotBaseFrame>
      </plugin>
      <plugin name='differential_drive_controller' filename='libgazebo_ros_diff_drive.so'>
        <robotNamespace>/mp500lwa4d</robotNamespace>
        <alwaysOn>true</alwaysOn>
        <updateRate>50</updateRate>
        <leftJoint>wheel_left_joint</leftJoint>
        <rightJoint>wheel_right_joint</rightJoint>
        <wheelSeparation>0.51</wheelSeparation>
        <wheelDiameter>0.25</wheelDiameter>
        <torque>100</torque>
        <commandTopic>/mobile_base_controller/cmd_vel</commandTopic>
        <odometryTopic>odom</odometryTopic>
        <odometryFrame>odom</odometryFrame>
        <robotBaseFrame>base_footprint</robotBaseFrame>
        <legacyMode>false</legacyMode>
        <rosDebugLevel>Debug</rosDebugLevel>
        <publishWheelTF>true</publishWheelTF>
        <publishWheelJointState>true</publishWheelJointState>
        <wheelAcceleration>10</wheelAcceleration>
        <wheelTorque>100</wheelTorque>
        <publishTf>1</publishTf>
        <odometrySource>encoder</odometrySource>
      </plugin>
      <pose frame=''>0 0 0 0 -0 0</pose>
    </model>
    <model name='ground_plane_0'>
      <static>1</static>
      <link name='link'>
        <collision name='collision'>
          <geometry>
            <plane>
              <normal>0 0 1</normal>
              <size>100 100</size>
            </plane>
          </geometry>
          <surface>
            <contact>
              <collide_bitmask>65535</collide_bitmask>
              <ode/>
            </contact>
            <friction>
              <ode>
                <mu>100</mu>
                <mu2>50</mu2>
              </ode>
              <torsional>
                <ode/>
              </torsional>
            </friction>
            <bounce/>
          </surface>
          <max_contacts>10</max_contacts>
        </collision>
        <visual name='visual'>
          <cast_shadows>0</cast_shadows>
          <geometry>
            <plane>
              <normal>0 0 1</normal>
              <size>100 100</size>
            </plane>
          </geometry>
          <material>
            <script>
              <uri>file://media/materials/scripts/gazebo.material</uri>
              <name>Gazebo/Grey</name>
            </script>
          </material>
        </visual>
        <self_collide>0</self_collide>
        <enable_wind>0</enable_wind>
        <kinematic>0</kinematic>
      </link>
      <pose frame=''>-6.40473 0.635507 0 0 -0 0</pose>
    </model>
    <model name='Trianingroom'>
      <pose frame=''>-0.062472 0.033668 0 0 -0 0</pose>
      <link name='Wall_17'>
        <collision name='Wall_17_Collision'>
          <geometry>
            <box>
              <size>2.5 0.15 0.5</size>
            </box>
          </geometry>
          <pose frame=''>0 0 0.25 0 -0 0</pose>
          <max_contacts>10</max_contacts>
          <surface>
            <contact>
              <ode/>
            </contact>
            <bounce/>
            <friction>
              <torsional>
                <ode/>
              </torsional>
              <ode/>
            </friction>
          </surface>
        </collision>
        <visual name='Wall_17_Visual'>
          <pose frame=''>0 0 0.25 0 -0 0</pose>
          <geometry>
            <box>
              <size>2.5 0.15 0.5</size>
            </box>
          </geometry>
          <material>
            <script>
              <uri>file://media/materials/scripts/gazebo.material</uri>
              <name>Gazebo/Grey</name>
            </script>
            <ambient>1 1 1 1</ambient>
          </material>
          <meta>
            <layer>0</layer>
          </meta>
        </visual>
        <pose frame=''>-2.425 1.25 0 0 -0 1.5708</pose>
        <self_collide>0</self_collide>
        <enable_wind>0</enable_wind>
        <kinematic>0</kinematic>
      </link>
      <link name='Wall_18'>
        <collision name='Wall_18_Collision'>
          <geometry>
            <box>
              <size>5 0.15 0.5</size>
            </box>
          </geometry>
          <pose frame=''>0 0 0.25 0 -0 0</pose>
          <max_contacts>10</max_contacts>
          <surface>
            <contact>
              <ode/>
            </contact>
            <bounce/>
            <friction>
              <torsional>
                <ode/>
              </torsional>
              <ode/>
            </friction>
          </surface>
        </collision>
        <visual name='Wall_18_Visual'>
          <pose frame=''>0 0 0.25 0 -0 0</pose>
          <geometry>
            <box>
              <size>5 0.15 0.5</size>
            </box>
          </geometry>
          <material>
            <script>
              <uri>file://media/materials/scripts/gazebo.material</uri>
              <name>Gazebo/Grey</name>
            </script>
            <ambient>1 1 1 1</ambient>
          </material>
          <meta>
            <layer>0</layer>
          </meta>
        </visual>
        <pose frame=''>-0 2.425 0 0 -0 0</pose>
        <self_collide>0</self_collide>
        <enable_wind>0</enable_wind>
        <kinematic>0</kinematic>
      </link>
      <link name='Wall_19'>
        <collision name='Wall_19_Collision'>
          <geometry>
            <box>
              <size>5 0.15 0.5</size>
            </box>
          </geometry>
          <pose frame=''>0 0 0.25 0 -0 0</pose>
          <max_contacts>10</max_contacts>
          <surface>
            <contact>
              <ode/>
            </contact>
            <bounce/>
            <friction>
              <torsional>
                <ode/>
              </torsional>
              <ode/>
            </friction>
          </surface>
        </collision>
        <visual name='Wall_19_Visual'>
          <pose frame=''>0 0 0.25 0 -0 0</pose>
          <geometry>
            <box>
              <size>5 0.15 0.5</size>
            </box>
          </geometry>
          <material>
            <script>
              <uri>file://media/materials/scripts/gazebo.material</uri>
              <name>Gazebo/Grey</name>
            </script>
            <ambient>1 1 1 1</ambient>
          </material>
          <meta>
            <layer>0</layer>
          </meta>
        </visual>
        <pose frame=''>2.425 -0 0 0 -0 -1.5708</pose>
        <self_collide>0</self_collide>
        <enable_wind>0</enable_wind>
        <kinematic>0</kinematic>
      </link>
      <link name='Wall_20'>
        <collision name='Wall_20_Collision'>
          <geometry>
            <box>
              <size>5 0.15 0.5</size>
            </box>
          </geometry>
          <pose frame=''>0 0 0.25 0 -0 0</pose>
          <max_contacts>10</max_contacts>
          <surface>
            <contact>
              <ode/>
            </contact>
            <bounce/>
            <friction>
              <torsional>
                <ode/>
              </torsional>
              <ode/>
            </friction>
          </surface>
        </collision>
        <visual name='Wall_20_Visual'>
          <pose frame=''>0 0 0.25 0 -0 0</pose>
          <geometry>
            <box>
              <size>5 0.15 0.5</size>
            </box>
          </geometry>
          <material>
            <script>
              <uri>file://media/materials/scripts/gazebo.material</uri>
              <name>Gazebo/Grey</name>
            </script>
            <ambient>1 1 1 1</ambient>
          </material>
          <meta>
            <layer>0</layer>
          </meta>
        </visual>
        <pose frame=''>-0 -2.425 0 0 -0 3.14159</pose>
        <self_collide>0</self_collide>
        <enable_wind>0</enable_wind>
        <kinematic>0</kinematic>
      </link>
      <link name='Wall_21'>
        <collision name='Wall_21_Collision'>
          <geometry>
            <box>
              <size>2.65 0.15 0.5</size>
            </box>
          </geometry>
          <pose frame=''>0 0 0.25 0 -0 0</pose>
          <max_contacts>10</max_contacts>
          <surface>
            <contact>
              <ode/>
            </contact>
            <bounce/>
            <friction>
              <torsional>
                <ode/>
              </torsional>
              <ode/>
            </friction>
          </surface>
        </collision>
        <visual name='Wall_21_Visual'>
          <pose frame=''>0 0 0.25 0 -0 0</pose>
          <geometry>
            <box>
              <size>2.65 0.15 0.5</size>
            </box>
          </geometry>
          <material>
            <script>
              <uri>file://media/materials/scripts/gazebo.material</uri>
              <name>Gazebo/Grey</name>
            </script>
            <ambient>1 1 1 1</ambient>
          </material>
          <meta>
            <layer>0</layer>
          </meta>
        </visual>
        <pose frame=''>-2.425 -1.175 0 0 -0 1.5708</pose>
        <self_collide>0</self_collide>
        <enable_wind>0</enable_wind>
        <kinematic>0</kinematic>
      </link>
      <static>1</static>
    </model>
    <state world_name='default'>
      <sim_time>259 184000000</sim_time>
      <real_time>491 501231088</real_time>
      <wall_time>1550359222 731828427</wall_time>
      <iterations>185297</iterations>
      <model name='Trianingroom'>
        <pose frame=''>-0.06247 0.03367 0 0 -0 0</pose>
        <scale>1 1 1</scale>
        <link name='Wall_17'>
          <pose frame=''>-2.48747 1.28367 0 0 -0 1.5708</pose>
          <velocity>0 0 0 0 -0 0</velocity>
          <acceleration>0 0 0 0 -0 0</acceleration>
          <wrench>0 0 0 0 -0 0</wrench>
        </link>
        <link name='Wall_18'>
          <pose frame=''>-0.062472 2.45867 0 0 -0 0</pose>
          <velocity>0 0 0 0 -0 0</velocity>
          <acceleration>0 0 0 0 -0 0</acceleration>
          <wrench>0 0 0 0 -0 0</wrench>
        </link>
        <link name='Wall_19'>
          <pose frame=''>2.36253 0.033668 0 0 0 -1.5708</pose>
          <velocity>0 0 0 0 -0 0</velocity>
          <acceleration>0 0 0 0 -0 0</acceleration>
          <wrench>0 0 0 0 -0 0</wrench>
        </link>
        <link name='Wall_20'>
          <pose frame=''>-0.062472 -2.39133 0 0 -0 3.14159</pose>
          <velocity>0 0 0 0 -0 0</velocity>
          <acceleration>0 0 0 0 -0 0</acceleration>
          <wrench>0 0 0 0 -0 0</wrench>
        </link>
        <link name='Wall_21'>
          <pose frame=''>-2.48747 -1.14133 0 0 -0 1.5708</pose>
          <velocity>0 0 0 0 -0 0</velocity>
          <acceleration>0 0 0 0 -0 0</acceleration>
          <wrench>0 0 0 0 -0 0</wrench>
        </link>
      </model>
      <model name='goal'>
        <pose frame=''>0 0 1 0 -0 0</pose>
        <scale>1 1 1</scale>
        <link name='Goal'>
          <pose frame=''>0 0 1 0 -0 0</pose>
          <velocity>0 0 0 0 -0 0</velocity>
          <acceleration>0 0 0 0 -0 0</acceleration>
          <wrench>0 0 0 0 -0 0</wrench>
        </link>
      </model>
      <model name='ground_plane'>
        <pose frame=''>0 0 0 0 -0 0</pose>
        <scale>1 1 1</scale>
        <link name='link'>
          <pose frame=''>0 0 0 0 -0 0</pose>
          <velocity>0 0 0 0 -0 0</velocity>
          <acceleration>0 0 0 0 -0 0</acceleration>
          <wrench>0 0 0 0 -0 0</wrench>
        </link>
      </model>
      <model name='ground_plane_0'>
        <pose frame=''>-6.40473 0.635507 0 0 -0 0</pose>
        <scale>1 1 1</scale>
        <link name='link'>
          <pose frame=''>-6.40473 0.635507 0 0 -0 0</pose>
          <velocity>0 0 0 0 -0 0</velocity>
          <acceleration>0 0 0 0 -0 0</acceleration>
          <wrench>0 0 0 0 -0 0</wrench>
        </link>
      </model>
      <model name='mp500lwa4d'>
        <pose frame=''>0.000141 -8e-06 -0.004544 3e-05 -0.002716 0.000276</pose>
        <scale>1 1 1</scale>
        <link name='arm_1_link'>
          <pose frame=''>0.188782 2.9e-05 0.49597 3e-05 -0.002716 0.000273</pose>
          <velocity>1.6e-05 -1e-06 1.4e-05 -1e-06 2.7e-05 0.000943</velocity>
          <acceleration>-0 -1e-06 0 -6.7e-05 -1e-06 0.024961</acceleration>
          <wrench>-0 -0 0 0 -0 0</wrench>
        </link>
        <link name='arm_2_link'>
          <pose frame=''>0.18813 2.2e-05 0.735969 1.56 -1.56804 -3.13053</pose>
          <velocity>2.4e-05 -1e-06 1.3e-05 -2e-06 2.5e-05 0.000943</velocity>
          <acceleration>-0 -1e-06 0 -6.7e-05 -1e-06 0.024961</acceleration>
          <wrench>-0 -0 0 0 -0 0</wrench>
        </link>
        <link name='arm_3_link'>
          <pose frame=''>0.18813 2.2e-05 0.735969 3e-05 -0.002753 0.000271</pose>
          <velocity>2.3e-05 -1e-06 1.3e-05 -4e-06 2.2e-05 0.001756</velocity>
          <acceleration>-0 -1e-06 0 -0.000126 -2e-06 0.046374</acceleration>
          <wrench>-0 -0 0 0 -0 0</wrench>
        </link>
        <link name='arm_4_link'>
          <pose frame=''>0.187227 1.2e-05 1.06397 1.56003 -1.56803 -3.13056</pose>
          <velocity>3.1e-05 -2e-06 1.3e-05 -4e-06 2.2e-05 0.001756</velocity>
          <acceleration>-0 -2e-06 0 -0.000126 -2e-06 0.046374</acceleration>
          <wrench>-0 -0 0 0 -0 0</wrench>
        </link>
        <link name='arm_5_link'>
          <pose frame=''>0.187227 1.2e-05 1.06397 3e-05 -0.002757 0.000269</pose>
          <velocity>3.1e-05 -2e-06 1.3e-05 -6e-06 2.1e-05 0.002325</velocity>
          <acceleration>-0 -2e-06 0 -0.000164 -2e-06 0.060221</acceleration>
          <wrench>-0 -0 0 0 -0 0</wrench>
        </link>
        <link name='arm_6_link'>
          <pose frame=''>0.186337 2e-06 1.38697 1.56004 -1.56803 -3.13057</pose>
          <velocity>3.8e-05 -2e-06 1.3e-05 -6e-06 -8e-06 0.002325</velocity>
          <acceleration>-0 -2e-06 0 -0.000164 -2e-06 0.060221</acceleration>
          <wrench>-0 -0 0 0 -0 0</wrench>
        </link>
        <link name='arm_7_link'>
          <pose frame=''>0.186337 2e-06 1.38697 3e-05 -0.002757 0.000268</pose>
          <velocity>3.8e-05 -2e-06 1.3e-05 -7e-06 -8e-06 0.002573</velocity>
          <acceleration>-0 -2e-06 0 -0.000182 -2e-06 0.066608</acceleration>
          <wrench>-0 -0 0 0 -0 0</wrench>
        </link>
        <link name='base_footprint'>
          <pose frame=''>0.000141 -8e-06 -0.004544 3e-05 -0.002716 0.000276</pose>
          <velocity>-0 0 1.8e-05 2e-06 3.3e-05 0</velocity>
          <acceleration>-0 -1e-06 -0 2e-06 0 4e-06</acceleration>
          <wrench>-0 -1e-06 -0 0 -0 0</wrench>
        </link>
        <link name='gripper_finger_left_link'>
          <pose frame=''>0.185798 -0.010008 1.58326 3e-05 -0.002757 0.000268</pose>
          <velocity>6.2e-05 -2e-06 1.3e-05 -7e-06 -9e-06 0.002573</velocity>
          <acceleration>0.000666 -2e-06 2e-06 -0.000182 -2e-06 0.066617</acceleration>
          <wrench>1e-06 -0 0 0 -0 0</wrench>
        </link>
        <link name='gripper_finger_right_link'>
          <pose frame=''>0.185793 0.010004 1.58327 3e-05 -0.002757 0.000268</pose>
          <velocity>1.1e-05 -2e-06 1.3e-05 -7e-06 -9e-06 0.002573</velocity>
          <acceleration>-0.000667 -3e-06 -2e-06 -0.000182 -2e-06 0.066617</acceleration>
          <wrench>-1e-06 -0 -0 0 -0 0</wrench>
        </link>
        <link name='wheel_left_link'>
          <pose frame=''>-0.155282 0.254945 0.125042 3.14156 0.653818 -3.14134</pose>
          <velocity>4e-06 -0 2.6e-05 1e-06 3.3e-05 0</velocity>
          <acceleration>-1e-06 -1e-06 0 1.1e-05 -8e-06 4e-06</acceleration>
          <wrench>-1e-06 -1e-06 0 0 -0 0</wrench>
        </link>
        <link name='wheel_right_link'>
          <pose frame=''>-0.155141 -0.255055 0.125027 0.001687 -1.55284 -0.001411</pose>
          <velocity>4e-06 -0 2.5e-05 3e-06 3.3e-05 0</velocity>
          <acceleration>1e-06 -1e-06 -0 1.2e-05 6e-06 4e-06</acceleration>
          <wrench>1e-06 -1e-06 -0 0 -0 0</wrench>
        </link>
      </model>
      <light name='sun'>
        <pose frame=''>0 0 10 0 -0 0</pose>
      </light>
    </state>
    <gui fullscreen='0'>
      <camera name='user_camera'>
        <pose frame=''>1.59013 -1.68734 7.04624 -0 1.13773 2.42184</pose>
        <view_controller>orbit</view_controller>
        <projection_type>perspective</projection_type>
      </camera>
    </gui>
  </world>
</sdf>