<?xml version="1.0"?>
<!-- Materials -->
<robot xmlns:xacro="http://www.ros.org/wiki/xacro" name="mp_500">
    
    <material name="Neobotix/Black">
        <color rgba="0.0 0.0 0.0 1.0"/>
    </material>

    <material name="Neobotix/Blue">
        <color rgba="0.0 0.0 0.8 1.0"/>
    </material>

    <material name="Neobotix/Green">
        <color rgba="0.0 0.8 0.0 1.0"/>
    </material>

    <material name="Neobotix/Grey">
        <color rgba="0.7 0.7 0.7 1.0"/>
    </material>

    <material name="Neobotix/Grey2">
        <color rgba="0.9 0.9 0.9 1.0"/>
    </material>

    <material name="Neobotix/Red">
        <color rgba="0.8 0.0 0.0 1.0"/>
    </material>

    <material name="Neobotix/White">
        <color rgba="1.0 1.0 1.0 1.0"/>
    </material>
    
    <material name="Neobotix/Yellow">
        <color rgba="1.0 1.0 0 10" />
    </material>

<!--++++++++++++++++++++++++++++++base_link++++++++++++++++++++++++++++++++++++++++++++++++++++--> 
<!--++++++++++++++++++++body++++++++++++++++++++++++++++--> 
  <link name="base_link">
      <!--inertial>
        <mass value="67.010" />
        <origin xyz="0.0 0.0 0.234" rpy="0 0 0"/>
        <inertia ixx="1417853.715" ixy="17813.155" ixz="-21078.206"
                 iyy="2030191.708" iyz="-4813.295" 
                 izz="2180211.662" />
      </inertial-->
	  <inertial>
		  <mass value="5.67" />
		    <origin xyz="0 0 0.01" rpy="0 0 0"/>
		    <inertia ixx="0.07" ixy="0.0" ixz="0.0"
		             iyy="0.08" iyz="0.0" 
		             izz="0.1" />
	  </inertial>
      <visual name='body'>
        <!--origin xyz="0.0 0.0 0.234" rpy="0 0 1.57" /--><!-- for cylinder -->
	<!--origin xyz="0.0 0.0 0.09" rpy="0 0 0" /--><!-- for STL -->
              <!--geometry>
                 <mesh filename="package://neo_mp_500/robot_model/mp_500/meshes/BODY.STL" scale="0.01 0.01 0.01"/>
	    	<cylinder length="0.381" radius="0.2545"/>
	    	<box size="0.445 0.277 0.17"/>
              </geometry-->
          <origin xyz="0 0.10 0.244" rpy="0 0 0" />
            <geometry>
            <box size="0.400 0.600 0.320"/>
          <!--cylinder length="0.381" radius="0.2545"/-->
        </geometry>
        <material name="Neobotix/Grey" />
       </visual>
      <collision name='body_collision'>
        <origin xyz="0 0.10 0.244" rpy="0 0 0" />
        <geometry>
          <box size="0.400 0.600 0.320"/>
          <!--cylinder length="0.381" radius="0.2545"/-->
        </geometry>
      </collision>
</link>
<!--+++++++++++++++++++castor_front++++++++++++++++++++++++--> 
<!--	<visual name='castor_front_visual'>
          <origin xyz="1.2 0 0.028" rpy="0 0 0" />
          <geometry>
            <sphere radius="0.016"/>
          </geometry>
          <material name="Neobotix/Black" />
      </visual>
      <collision name='castor_front_collision'>
	  	<origin xyz="1.2 0 0.028 " rpy="0 0 0" />
          <geometry>
            <sphere radius="0.016"/>
          </geometry>
    </collision>-->
<!--+++++++++++++++++++castor_back++++++++++++++++++++++++--> 
	<!--<visual name='castor_back_visual'>
          <origin xyz="-1.2 0 0.028" rpy="0 0 0" />
          <geometry>
            <sphere radius="0.016"/>
          </geometry>
          <material name="Neobotix/Black" />
      </visual>
      <collision name='castor_back_collision'>
	  	<origin xyz="-1.2 0 0.028 " rpy="0 0 0" />-->
          <!--pose>0.3 0 -0.12 0 -0 0</pose-->
         <!-- <geometry>
            <sphere radius="0.016"/>
          </geometry>
       </collision>
    </link>-->

<!--+++++++++++++++++++wheel_left_link++++++++++++++++++++++++--> 
	<link name="wheel_left_link" type="wheel">
    	  <inertial>
      		<mass value="1.5" />
     		 <origin xyz="0 0 0.005" rpy="0 0 0" />
      		<inertia ixx="0.0051" ixy="0" ixz="0" iyy="0.0051" iyz="0" izz="0.009" />
    	  </inertial>

    <visual>
        <origin xyz="-0.255 0.005 0" rpy="0 1.57 0" />
     	<!--origin xyz="-0.255 0.005 0" rpy="0 0 0" /-->
     	<geometry>
		<!--mesh filename="package://neo_mp_500/robot_model/mp_500/meshes/WHEEL2.STL" scale="0.01 0.01 0.01" /--> 
                <cylinder radius="0.125" length="0.07"/>
     	</geometry>
     	<material name="Neobotix/Black" />
    </visual>
    <collision>
     	<origin xyz="-0.255 0.005 0" rpy="0 1.57 0" />
     	<geometry>
        	<cylinder radius="0.125" length="0.07"/>
     	</geometry>
    </collision>
			
</link>

<!--+++++++++++++++++++wheel_left_joint++++++++++++++++++++++++--> 
	<joint name="wheel_left_joint" type="revolute">
		<origin xyz="0 0 0.13" rpy="0 0 0" />
    	<axis xyz="1 0 0"/>
    	<limit effort="1000.0" lower="-1e+16" upper="1e+16" velocity="3.5"/>
    	<joint_properties damping="0.0" friction="0.0" />
    	<parent link="base_link" />
    	<child link="wheel_left_link" />
    </joint>

<!--+++++++++++++++++++wheel_right_link++++++++++++++++++++++++--> 
<!--Mesh Volume is 3587.704102
Mesh Surface is 1876.550415
Thin shell barycenter -25.340059 -0.000027 4.499997
Center of Mass is -25.340000 -0.000164 4.500009
Inertia Tensor is :
| 322624.937500 -0.068522 -1.293689 |
| -0.068522 179104.328125 -1.342927 |
| -1.293689 -1.342927 179079.796875 |
Principal axes are :
| 1.000000 -0.000000 0.000009 |
| -0.000000 0.998514 0.054499 |
| -0.000009 -0.054499 0.998514 |
axis momenta are :
| 322624.937500 179104.406250 179079.718750 |
Mesh Volume is 0.000000
Mesh Surface is 0.000019
Thin shell barycenter -0.002534 -0.000000 0.000450
Center of Mass is -0.002534 -0.000000 0.000450
Inertia Tensor is :
| 0.000000 -0.000000 -0.000000 |
| -0.000000 0.000000 -0.000000 |
| -0.000000 -0.000000 0.000000 |
Principal axes are :
| 1.000000 -0.000000 0.000009 |
| -0.000000 0.998526 0.054276 |
| -0.000009 -0.054276 0.998526 |
axis momenta are :
| 0.000000 0.000000 0.000000 | -->
<link name="wheel_right_link" type="wheel">
	<inertial>
		  <mass value="1.5" />
		  <origin xyz="0 0 0.005" rpy="0 0 0" />
		  <inertia ixx="0.0051" ixy="0" ixz="0" iyy="0.0051" iyz="0" izz="0.009" />
	</inertial>

		<visual>
		 	<!--origin xyz="0.255 0.005 0" rpy="0 0 0" />
		 	<geometry>
				<mesh filename="package://neo_mp_500/robot_model/mp_500/meshes/WHEEL2.STL" scale="0.01 0.01 0.01" />
		 	</geometry>
		 	<material name="Neobotix/Grey" /-->
                        <origin xyz="0.255 0.005 0" rpy="0 1.57 0" />
		 	<geometry>
		    	<cylinder radius="0.125" length="0.07"/>
		 	</geometry>
                <material name="Neobotix/Black"/>
		</visual>

		<collision>
		 	<origin xyz="0.255 0.005 0" rpy="0 1.57 0" />
		 	<geometry>
		    	<cylinder radius="0.125" length="0.07"/>
		 	</geometry>
		</collision>
	</link>

<!--+++++++++++++++++++wheel_right_joint++++++++++++++++++++++++--> 
	<joint name="wheel_right_joint" type="revolute">
    	<origin xyz="0 0 0.13" rpy="0 0 0" />
    	<axis xyz="1 0 0"/>
    	<limit effort="1000.0" lower="-1e+16" upper="1e+16" velocity="3.5"/>
    	<joint_properties damping="0.0" friction="0.0" />
    	<parent link="base_link" />
    	<child link="wheel_right_link" />
    </joint>


<!--+++++++++++++++++++laserscanner_front_joint++++++++++++++++++++++++--> 
	<joint name="laserscanner_front_joint" type="fixed">
		  <axis xyz="0 0 1" />
		  <origin xyz="0 -0.244 0.141" rpy="0 3.14 0" />
		  <parent link="base_link"/>
		  <child link="laserscanner_front_link"/>
	</joint>

<!--+++++++++++++++++++laserscanner_front_link++++++++++++++++++++++++-->
	<link name="laserscanner_front_link" type="laser">
		<inertial>
			<mass value="0.001" />
			<origin xyz="0 0 0" rpy="0 0 0" />
			<inertia ixx="0.0001" ixy="0" ixz="0" iyy="0.000001" iyz="0" izz="0.0001" />
	  	</inertial>
	  	<visual>
			<origin xyz="0 0 -0.04" rpy="0 0 3.14" />
			<geometry>
                             <cylinder length="0.154" radius="0.053" />		  		
                             <!--mesh filename="package://neo_mp_500/robot_model/mp_500/meshes/SICK-S300.STL" /-->
			</geometry>
			<material name="Neobotix/Yellow" />
	  	</visual>
	  	<collision>
			<origin xyz="0 0 -0.04" rpy="0 0 3.14" />
			<geometry>
		  	<cylinder length="0.154" radius="0.053" />
			</geometry>
	  	</collision>
	</link>
<!--+++++++++++++++ wheel_hanger+++++++++++++++++++++++++++-->
<link name="hanger">
	<inertial>
		  <mass value="0.5" />
		  <origin xyz="0 0 0" rpy="0 0 0" />
		  <inertia ixx="0.00051" ixy="0" ixz="0" iyy="0.00051" iyz="0" izz="0.0009" />
	</inertial>
	<visual>
	 	<!--origin xyz="0.01 0.23 0" rpy="0 0 0" />
	 	<geometry>
		      <mesh filename="package://neo_mp_500/robot_model/mp_500/meshes/HANGER-WHEEL2.STL" scale="0.01 0.01 0.01" />
		 </geometry-->
                 <origin xyz="0 0.23 0" rpy="0 0 0" />
		 <geometry>
          	 <sphere radius="0.115"/>
		 </geometry>
		 <material name="Neobotix/Grey" />
	</visual>
        <collision>
		 <origin xyz="0 0.23 0" rpy="0 0 0" />
		 <geometry>
          	 <sphere radius="0.115"/>
		 </geometry>
	</collision>
</link>

<joint name="hanger_joint" type="fixed">
    	<origin xyz="-0.004 0.23 0.12" rpy="0 0 0"/>
    	<axis xyz="0 0 1"/>
        <limit effort="1000.0" lower="-1e+16" upper="1e+16" velocity="3.5"/>
    	<joint_properties damping="0.0" friction="0.0" />
    	<parent link="base_link" />
    	<child link="hanger" />
    </joint>

<!--+++++++++++++++++++hanger_joint++++++++++++++++++++++++--> 
<!--+++++++++++++++++++wheel_front_joint++++++++++++++++++++++++--> 

<!--+++++++++++++++++++castor++++++++++++++++++++++++--> 
<!--link name="castor_front" type="castor">
	<inertial>
		  <mass value="0.01" />
		  <origin xyz="0 0 0" rpy="0 0 0" />
		  <inertia ixx="0.000051" ixy="0" ixz="0.000051" iyy="0.000051" iyz="0.000051" izz="0.000051" />
	</inertial>

	<visual>
	  <origin xyz="0 0.45 0 " rpy="0 0 0" />
	          <geometry>  
                    <castor radius="0.075"/>
		 </geometry>
		 <material name="Neobotix/Black" />
	</visual>

	<collision>
	    <origin xyz="0 0.45 0 " rpy="0 0 0" />
	 	<geometry>  
                   <castor radius="0.075"/>
		 </geometry>
	</collision>
</link>

<joint name="castor_joint" type="castor">
    	<origin xyz="0 0 0" rpy="0 0 0" />
    	<axis xyz="0 0 1"/>
        <limit effort="1000.0" lower="-1e+16" upper="1e+16" velocity="3.5"/>
    	<joint_properties damping="0.0" friction="0.0" />
    	<parent link="wheel_front_link" />
    	<child link="castor_front" />
</joint-->


<transmission name="wheel_left">
    <type>transmission_interface/SimpleTransmission</type>
    <joint name="wheel_left_joint">
      <hardwareInterface>EffortJointInterface</hardwareInterface>
    </joint>
    <actuator name="wheel_left_joint_motor">
      <hardwareInterface>EffortJointInterface</hardwareInterface>
      <mechanicalReduction>1</mechanicalReduction>
    </actuator>
  </transmission>

  <transmission name="wheel_right">
    <type>transmission_interface/SimpleTransmission</type>
    <joint name="wheel_right_joint">
      <hardwareInterface>EffortJointInterface</hardwareInterface>
    </joint>
    <actuator name="wheel_right_joint_motor">
      <hardwareInterface>EffortJointInterface</hardwareInterface>
      <mechanicalReduction>1</mechanicalReduction>
    </actuator>
  </transmission>

    <gazebo>
      <plugin name="differential_drive_controller" filename="libdiffdrive_plugin.so">
        <robotNamespace>mp_500</robotNamespace>
      </plugin>
    </gazebo>
    
</robot>
